test/test_cases/output1.csv
A, 1, 1
B, B, 10, 100
A, 1, 2
B, S, 12, 100
A, 2, 101
A, 2, 102
B, S, 11, 100
A, 1, 3
T, 1, 3, 2, 102, 11, 100
B, S, 12, 100
A, 2, 103
T, 1, 1, 2, 103, 10, 100
B, B, 9, 100
A, 1, 4
B, B, 10, 100
A, 2, 104
B, S, 11, 100
