test/test_cases/output13.csv
A, 1, 1
B, B, 10, 100
A, 1, 2
B, S, 12, 100
A, 2, 101
A, 2, 102
B, S, 11, 100
A, 2, 103
B, B, 10, 150
A, 1, 3
B, S, 11, 150
A, 1, 4
T, 1, 4, 1, 3, 11, 50
T, 1, 4, 2, 102, 11, 50
B, S, 11, 50
A, 2, 104
T, 2, 103, 2, 104, 10, 50
T, 1, 1, 2, 104, 10, 50
B, B, 10, 50
